Internal Server Error: /
Traceback (most recent call last):
  File "/home/cpasbanal/.virtualenvs/django19/lib/python3.5/site-packages/django/core/handlers/base.py", line 131, in get_response
    response = middleware_method(request, response)
  File "/home/cpasbanal/.virtualenvs/django19/lib/python3.5/site-packages/django/middleware/clickjacking.py", line 32, in process_response
    if response.get('X-Frame-Options') is not None:
AttributeError: 'str' object has no attribute 'get'
Exception while resolving variable 'is_popup' in template 'admin/login.html'.
Traceback (most recent call last):
  File "/home/cpasbanal/.virtualenvs/django19/lib/python3.5/site-packages/django/template/base.py", line 885, in _resolve_lookup
    current = current[bit]
  File "/home/cpasbanal/.virtualenvs/django19/lib/python3.5/site-packages/django/template/context.py", line 75, in __getitem__
    raise KeyError(key)
KeyError: 'is_popup'

During handling of the above exception, another exception occurred:

Traceback (most recent call last):
  File "/home/cpasbanal/.virtualenvs/django19/lib/python3.5/site-packages/django/template/base.py", line 891, in _resolve_lookup
    if isinstance(current, BaseContext) and getattr(type(current), bit):
AttributeError: type object 'RequestContext' has no attribute 'is_popup'

During handling of the above exception, another exception occurred:

Traceback (most recent call last):
  File "/home/cpasbanal/.virtualenvs/django19/lib/python3.5/site-packages/django/template/base.py", line 900, in _resolve_lookup
    current = current[int(bit)]
ValueError: invalid literal for int() with base 10: 'is_popup'

During handling of the above exception, another exception occurred:

Traceback (most recent call last):
  File "/home/cpasbanal/.virtualenvs/django19/lib/python3.5/site-packages/django/template/base.py", line 907, in _resolve_lookup
    (bit, current))  # missing attribute
django.template.base.VariableDoesNotExist: Failed lookup for key [is_popup] in "[{'False': False, 'None': None, 'True': True}, {'csrf_token': <SimpleLazyObject: <function csrf.<locals>._get_val at 0x7ffb6d395598>>, 'perms': <django.contrib.auth.context_processors.PermWrapper object at 0x7ffb6d3e6f60>, 'messages': <django.contrib.messages.storage.fallback.FallbackStorage object at 0x7ffb6d3c9390>, 'user': <SimpleLazyObject: <django.contrib.auth.models.AnonymousUser object at 0x7ffb6d3c9da0>>, 'request': <WSGIRequest: GET '/admin/login/?next=/admin/'>, 'DEFAULT_MESSAGE_LEVELS': {'SUCCESS': 25, 'ERROR': 40, 'DEBUG': 10, 'INFO': 20, 'WARNING': 30}}, {}, {'username': '', 'site_name': 'cpasbanal.pythonanywhere.com', 'LANGUAGE_CODE': 'en-us', 'LANGUAGE_BIDI': False, 'title': 'Log in', 'has_permission': False, 'form': <AdminAuthenticationForm bound=False, valid=Unknown, fields=(username;password)>, 'site_title': <django.utils.functional.lazy.<locals>.__proxy__ object at 0x7ffb7d15b198>, 'available_apps': [], 'site_header': <django.utils.functional.lazy.<locals>.__proxy__ object at 0x7ffb7d15b240>, 'next': '/admin/', 'site_url': '/', 'app_path': '/admin/login/?next=/admin/', 'site': <django.contrib.sites.requests.RequestSite object at 0x7ffb6d3c9cc0>}]"
Exception while resolving variable 'is_popup' in template 'admin/login.html'.
Traceback (most recent call last):
  File "/home/cpasbanal/.virtualenvs/django19/lib/python3.5/site-packages/django/template/base.py", line 885, in _resolve_lookup
    current = current[bit]
  File "/home/cpasbanal/.virtualenvs/django19/lib/python3.5/site-packages/django/template/context.py", line 75, in __getitem__
    raise KeyError(key)
KeyError: 'is_popup'

During handling of the above exception, another exception occurred:

Traceback (most recent call last):
  File "/home/cpasbanal/.virtualenvs/django19/lib/python3.5/site-packages/django/template/base.py", line 891, in _resolve_lookup
    if isinstance(current, BaseContext) and getattr(type(current), bit):
AttributeError: type object 'RequestContext' has no attribute 'is_popup'

During handling of the above exception, another exception occurred:

Traceback (most recent call last):
  File "/home/cpasbanal/.virtualenvs/django19/lib/python3.5/site-packages/django/template/base.py", line 900, in _resolve_lookup
    current = current[int(bit)]
ValueError: invalid literal for int() with base 10: 'is_popup'

During handling of the above exception, another exception occurred:

Traceback (most recent call last):
  File "/home/cpasbanal/.virtualenvs/django19/lib/python3.5/site-packages/django/template/base.py", line 907, in _resolve_lookup
    (bit, current))  # missing attribute
django.template.base.VariableDoesNotExist: Failed lookup for key [is_popup] in "[{'False': False, 'None': None, 'True': True}, {'csrf_token': <SimpleLazyObject: <function csrf.<locals>._get_val at 0x7ffb6d395598>>, 'perms': <django.contrib.auth.context_processors.PermWrapper object at 0x7ffb6d3e6f60>, 'messages': <django.contrib.messages.storage.fallback.FallbackStorage object at 0x7ffb6d3c9390>, 'user': <SimpleLazyObject: <django.contrib.auth.models.AnonymousUser object at 0x7ffb6d3c9da0>>, 'request': <WSGIRequest: GET '/admin/login/?next=/admin/'>, 'DEFAULT_MESSAGE_LEVELS': {'SUCCESS': 25, 'ERROR': 40, 'DEBUG': 10, 'INFO': 20, 'WARNING': 30}}, {}, {'username': '', 'site_name': 'cpasbanal.pythonanywhere.com', 'LANGUAGE_CODE': 'en-us', 'LANGUAGE_BIDI': False, 'title': 'Log in', 'has_permission': False, 'form': <AdminAuthenticationForm bound=False, valid=Unknown, fields=(username;password)>, 'site_title': <django.utils.functional.lazy.<locals>.__proxy__ object at 0x7ffb7d15b198>, 'available_apps': [], 'site_header': <django.utils.functional.lazy.<locals>.__proxy__ object at 0x7ffb7d15b240>, 'next': '/admin/', 'site_url': '/', 'app_path': '/admin/login/?next=/admin/', 'site': <django.contrib.sites.requests.RequestSite object at 0x7ffb6d3c9cc0>}]"
Exception while resolving variable 'name' in template 'unknown'.
Traceback (most recent call last):
  File "/home/cpasbanal/.virtualenvs/django19/lib/python3.5/site-packages/django/core/handlers/exception.py", line 39, in inner
    response = get_response(request)
  File "/home/cpasbanal/.virtualenvs/django19/lib/python3.5/site-packages/django/core/handlers/base.py", line 249, in _legacy_get_response
    response = self._get_response(request)
  File "/home/cpasbanal/.virtualenvs/django19/lib/python3.5/site-packages/django/core/handlers/base.py", line 172, in _get_response
    resolver_match = resolver.resolve(request.path_info)
  File "/home/cpasbanal/.virtualenvs/django19/lib/python3.5/site-packages/django/urls/resolvers.py", line 297, in resolve
    raise Resolver404({'tried': tried, 'path': new_path})
django.urls.exceptions.Resolver404: {'path': 'favicon.ico', 'tried': [[<RegexURLResolver <module 'rest_framework.urls' from '/home/cpasbanal/.virtualenvs/django19/lib/python3.5/site-packages/rest_framework/urls.py'> (rest_framework:rest_framework) ^api-auth/>], [<RegexURLResolver <module 'lunchy.urls' from '/home/cpasbanal/randomlunch/lunchy/urls.py'> (None:None) ^lunchy/>], [<RegexURLResolver <RegexURLPattern list> (admin:admin) ^admin/>], [<RegexURLPattern None ^$>]]}

During handling of the above exception, another exception occurred:

Traceback (most recent call last):
  File "/home/cpasbanal/.virtualenvs/django19/lib/python3.5/site-packages/django/template/base.py", line 885, in _resolve_lookup
    current = current[bit]
TypeError: 'RegexURLResolver' object is not subscriptable

During handling of the above exception, another exception occurred:

Traceback (most recent call last):
  File "/home/cpasbanal/.virtualenvs/django19/lib/python3.5/site-packages/django/template/base.py", line 893, in _resolve_lookup
    current = getattr(current, bit)
AttributeError: 'RegexURLResolver' object has no attribute 'name'

During handling of the above exception, another exception occurred:

Traceback (most recent call last):
  File "/home/cpasbanal/.virtualenvs/django19/lib/python3.5/site-packages/django/template/base.py", line 900, in _resolve_lookup
    current = current[int(bit)]
ValueError: invalid literal for int() with base 10: 'name'

During handling of the above exception, another exception occurred:

Traceback (most recent call last):
  File "/home/cpasbanal/.virtualenvs/django19/lib/python3.5/site-packages/django/template/base.py", line 907, in _resolve_lookup
    (bit, current))  # missing attribute
django.template.base.VariableDoesNotExist: Failed lookup for key [name] in "<RegexURLResolver <module 'rest_framework.urls' from '/home/cpasbanal/.virtualenvs/django19/lib/python3.5/site-packages/rest_framework/urls.py'> (rest_framework:rest_framework) ^api-auth/>"
Exception while resolving variable 'name' in template 'unknown'.
Traceback (most recent call last):
  File "/home/cpasbanal/.virtualenvs/django19/lib/python3.5/site-packages/django/core/handlers/exception.py", line 39, in inner
    response = get_response(request)
  File "/home/cpasbanal/.virtualenvs/django19/lib/python3.5/site-packages/django/core/handlers/base.py", line 249, in _legacy_get_response
    response = self._get_response(request)
  File "/home/cpasbanal/.virtualenvs/django19/lib/python3.5/site-packages/django/core/handlers/base.py", line 172, in _get_response
    resolver_match = resolver.resolve(request.path_info)
  File "/home/cpasbanal/.virtualenvs/django19/lib/python3.5/site-packages/django/urls/resolvers.py", line 297, in resolve
    raise Resolver404({'tried': tried, 'path': new_path})
django.urls.exceptions.Resolver404: {'path': 'favicon.ico', 'tried': [[<RegexURLResolver <module 'rest_framework.urls' from '/home/cpasbanal/.virtualenvs/django19/lib/python3.5/site-packages/rest_framework/urls.py'> (rest_framework:rest_framework) ^api-auth/>], [<RegexURLResolver <module 'lunchy.urls' from '/home/cpasbanal/randomlunch/lunchy/urls.py'> (None:None) ^lunchy/>], [<RegexURLResolver <RegexURLPattern list> (admin:admin) ^admin/>], [<RegexURLPattern None ^$>]]}

During handling of the above exception, another exception occurred:

Traceback (most recent call last):
  File "/home/cpasbanal/.virtualenvs/django19/lib/python3.5/site-packages/django/template/base.py", line 885, in _resolve_lookup
    current = current[bit]
TypeError: 'RegexURLResolver' object is not subscriptable

During handling of the above exception, another exception occurred:

Traceback (most recent call last):
  File "/home/cpasbanal/.virtualenvs/django19/lib/python3.5/site-packages/django/template/base.py", line 893, in _resolve_lookup
    current = getattr(current, bit)
AttributeError: 'RegexURLResolver' object has no attribute 'name'

During handling of the above exception, another exception occurred:

Traceback (most recent call last):
  File "/home/cpasbanal/.virtualenvs/django19/lib/python3.5/site-packages/django/template/base.py", line 900, in _resolve_lookup
    current = current[int(bit)]
ValueError: invalid literal for int() with base 10: 'name'

During handling of the above exception, another exception occurred:

Traceback (most recent call last):
  File "/home/cpasbanal/.virtualenvs/django19/lib/python3.5/site-packages/django/template/base.py", line 907, in _resolve_lookup
    (bit, current))  # missing attribute
django.template.base.VariableDoesNotExist: Failed lookup for key [name] in "<RegexURLResolver <module 'lunchy.urls' from '/home/cpasbanal/randomlunch/lunchy/urls.py'> (None:None) ^lunchy/>"
Exception while resolving variable 'name' in template 'unknown'.
Traceback (most recent call last):
  File "/home/cpasbanal/.virtualenvs/django19/lib/python3.5/site-packages/django/core/handlers/exception.py", line 39, in inner
    response = get_response(request)
  File "/home/cpasbanal/.virtualenvs/django19/lib/python3.5/site-packages/django/core/handlers/base.py", line 249, in _legacy_get_response
    response = self._get_response(request)
  File "/home/cpasbanal/.virtualenvs/django19/lib/python3.5/site-packages/django/core/handlers/base.py", line 172, in _get_response
    resolver_match = resolver.resolve(request.path_info)
  File "/home/cpasbanal/.virtualenvs/django19/lib/python3.5/site-packages/django/urls/resolvers.py", line 297, in resolve
    raise Resolver404({'tried': tried, 'path': new_path})
django.urls.exceptions.Resolver404: {'path': 'favicon.ico', 'tried': [[<RegexURLResolver <module 'rest_framework.urls' from '/home/cpasbanal/.virtualenvs/django19/lib/python3.5/site-packages/rest_framework/urls.py'> (rest_framework:rest_framework) ^api-auth/>], [<RegexURLResolver <module 'lunchy.urls' from '/home/cpasbanal/randomlunch/lunchy/urls.py'> (None:None) ^lunchy/>], [<RegexURLResolver <RegexURLPattern list> (admin:admin) ^admin/>], [<RegexURLPattern None ^$>]]}

During handling of the above exception, another exception occurred:

Traceback (most recent call last):
  File "/home/cpasbanal/.virtualenvs/django19/lib/python3.5/site-packages/django/template/base.py", line 885, in _resolve_lookup
    current = current[bit]
TypeError: 'RegexURLResolver' object is not subscriptable

During handling of the above exception, another exception occurred:

Traceback (most recent call last):
  File "/home/cpasbanal/.virtualenvs/django19/lib/python3.5/site-packages/django/template/base.py", line 893, in _resolve_lookup
    current = getattr(current, bit)
AttributeError: 'RegexURLResolver' object has no attribute 'name'

During handling of the above exception, another exception occurred:

Traceback (most recent call last):
  File "/home/cpasbanal/.virtualenvs/django19/lib/python3.5/site-packages/django/template/base.py", line 900, in _resolve_lookup
    current = current[int(bit)]
ValueError: invalid literal for int() with base 10: 'name'

During handling of the above exception, another exception occurred:

Traceback (most recent call last):
  File "/home/cpasbanal/.virtualenvs/django19/lib/python3.5/site-packages/django/template/base.py", line 907, in _resolve_lookup
    (bit, current))  # missing attribute
django.template.base.VariableDoesNotExist: Failed lookup for key [name] in '<RegexURLResolver <RegexURLPattern list> (admin:admin) ^admin/>'
Not Found: /favicon.ico
(0.009) SELECT "auth_user"."id", "auth_user"."password", "auth_user"."last_login", "auth_user"."is_superuser", "auth_user"."username", "auth_user"."first_name", "auth_user"."last_name", "auth_user"."email", "auth_user"."is_staff", "auth_user"."is_active", "auth_user"."date_joined" FROM "auth_user" WHERE "auth_user"."username" = 'jeremie'; args=('jeremie',)
(0.000) BEGIN; args=None
(0.010) UPDATE "auth_user" SET "password" = 'pbkdf2_sha256$30000$oiF5CFOburN8$TFymUzHxFkpVBdFECqR+yqhbFAvbB0g8QR/tVDgmRIc=' WHERE "auth_user"."id" = 1; args=('pbkdf2_sha256$30000$oiF5CFOburN8$TFymUzHxFkpVBdFECqR+yqhbFAvbB0g8QR/tVDgmRIc=', 1)
(0.011) SELECT (1) AS "a" FROM "django_session" WHERE "django_session"."session_key" = 'f1nj6eq6unx1frkg7dgsqqx6d20k0an3' LIMIT 1; args=('f1nj6eq6unx1frkg7dgsqqx6d20k0an3',)
(0.000) BEGIN; args=None
(0.026) INSERT INTO "django_session" ("session_key", "session_data", "expire_date") SELECT 'f1nj6eq6unx1frkg7dgsqqx6d20k0an3', 'OTRjMTc3NDc0MTI2NDhlMWVhNWU4MjdmMGNlZDllYzNmMDZlYTc4Njp7fQ==', '2016-09-05 12:33:27.888270'; args=('f1nj6eq6unx1frkg7dgsqqx6d20k0an3', 'OTRjMTc3NDc0MTI2NDhlMWVhNWU4MjdmMGNlZDllYzNmMDZlYTc4Njp7fQ==', '2016-09-05 12:33:27.888270')
(0.000) BEGIN; args=None
(0.006) UPDATE "auth_user" SET "last_login" = '2016-08-22 12:33:27.943978' WHERE "auth_user"."id" = 1; args=('2016-08-22 12:33:27.943978', 1)
(0.000) BEGIN; args=None
(0.004) UPDATE "django_session" SET "session_data" = 'MGI4ODQwN2JiNTUyOTRkMDMwNTg3ZWY2MDlhYzE4ZmFmY2IyMzRiNzp7Il9hdXRoX3VzZXJfYmFja2VuZCI6ImRqYW5nby5jb250cmliLmF1dGguYmFja2VuZHMuTW9kZWxCYWNrZW5kIiwiX2F1dGhfdXNlcl9oYXNoIjoiNDQ1MjhjMjUzZTYxZDFhZDhhYzJmMjQ4ZDA3YzlkZWRjNDkxYmEzOSIsIl9hdXRoX3VzZXJfaWQiOiIxIn0=', "expire_date" = '2016-09-05 12:33:27.972932' WHERE "django_session"."session_key" = 'f1nj6eq6unx1frkg7dgsqqx6d20k0an3'; args=('MGI4ODQwN2JiNTUyOTRkMDMwNTg3ZWY2MDlhYzE4ZmFmY2IyMzRiNzp7Il9hdXRoX3VzZXJfYmFja2VuZCI6ImRqYW5nby5jb250cmliLmF1dGguYmFja2VuZHMuTW9kZWxCYWNrZW5kIiwiX2F1dGhfdXNlcl9oYXNoIjoiNDQ1MjhjMjUzZTYxZDFhZDhhYzJmMjQ4ZDA3YzlkZWRjNDkxYmEzOSIsIl9hdXRoX3VzZXJfaWQiOiIxIn0=', '2016-09-05 12:33:27.972932', 'f1nj6eq6unx1frkg7dgsqqx6d20k0an3')
(0.011) SELECT "django_session"."session_key", "django_session"."session_data", "django_session"."expire_date" FROM "django_session" WHERE ("django_session"."session_key" = 'f1nj6eq6unx1frkg7dgsqqx6d20k0an3' AND "django_session"."expire_date" > '2016-08-22 12:33:28.092919'); args=('f1nj6eq6unx1frkg7dgsqqx6d20k0an3', '2016-08-22 12:33:28.092919')
(0.002) SELECT "auth_user"."id", "auth_user"."password", "auth_user"."last_login", "auth_user"."is_superuser", "auth_user"."username", "auth_user"."first_name", "auth_user"."last_name", "auth_user"."email", "auth_user"."is_staff", "auth_user"."is_active", "auth_user"."date_joined" FROM "auth_user" WHERE "auth_user"."id" = 1; args=(1,)
Exception while resolving variable 'is_popup' in template 'admin/index.html'.
Traceback (most recent call last):
  File "/home/cpasbanal/.virtualenvs/django19/lib/python3.5/site-packages/django/template/base.py", line 885, in _resolve_lookup
    current = current[bit]
  File "/home/cpasbanal/.virtualenvs/django19/lib/python3.5/site-packages/django/template/context.py", line 75, in __getitem__
    raise KeyError(key)
KeyError: 'is_popup'

During handling of the above exception, another exception occurred:

Traceback (most recent call last):
  File "/home/cpasbanal/.virtualenvs/django19/lib/python3.5/site-packages/django/template/base.py", line 891, in _resolve_lookup
    if isinstance(current, BaseContext) and getattr(type(current), bit):
AttributeError: type object 'RequestContext' has no attribute 'is_popup'

During handling of the above exception, another exception occurred:

Traceback (most recent call last):
  File "/home/cpasbanal/.virtualenvs/django19/lib/python3.5/site-packages/django/template/base.py", line 900, in _resolve_lookup
    current = current[int(bit)]
ValueError: invalid literal for int() with base 10: 'is_popup'

During handling of the above exception, another exception occurred:

Traceback (most recent call last):
  File "/home/cpasbanal/.virtualenvs/django19/lib/python3.5/site-packages/django/template/base.py", line 907, in _resolve_lookup
    (bit, current))  # missing attribute
django.template.base.VariableDoesNotExist: Failed lookup for key [is_popup] in "[{'False': False, 'None': None, 'True': True}, {'csrf_token': <SimpleLazyObject: <function csrf.<locals>._get_val at 0x7ffb6d4236a8>>, 'perms': <django.contrib.auth.context_processors.PermWrapper object at 0x7ffb6d3ebeb8>, 'messages': <django.contrib.messages.storage.fallback.FallbackStorage object at 0x7ffb6d3e2080>, 'user': <SimpleLazyObject: <User: jeremie>>, 'request': <WSGIRequest: GET '/admin/'>, 'DEFAULT_MESSAGE_LEVELS': {'SUCCESS': 25, 'ERROR': 40, 'DEBUG': 10, 'INFO': 20, 'WARNING': 30}}, {}, {'site_title': <django.utils.functional.lazy.<locals>.__proxy__ object at 0x7ffb7d15b198>, 'app_list': [{'has_module_perms': True, 'name': <django.utils.functional.lazy.<locals>.__proxy__ object at 0x7ffb7d10e240>, 'app_url': '/admin/authtoken/', 'models': [{'add_url': '/admin/authtoken/token/add/', 'name': <django.utils.functional.lazy.<locals>.__proxy__ object at 0x7ffb6d3e2128>, 'perms': {'change': True, 'delete': True, 'add': True}, 'admin_url': '/admin/authtoken/token/', 'object_name': 'Token'}], 'app_label': 'authtoken'}, {'has_module_perms': True, 'name': <django.utils.functional.lazy.<locals>.__proxy__ object at 0x7ffb7d3d8320>, 'app_url': '/admin/auth/', 'models': [{'add_url': '/admin/auth/group/add/', 'name': <django.utils.functional.lazy.<locals>.__proxy__ object at 0x7ffb6d357748>, 'perms': {'change': True, 'delete': True, 'add': True}, 'admin_url': '/admin/auth/group/', 'object_name': 'Group'}, {'add_url': '/admin/auth/user/add/', 'name': <django.utils.functional.lazy.<locals>.__proxy__ object at 0x7ffb6d3e2668>, 'perms': {'change': True, 'delete': True, 'add': True}, 'admin_url': '/admin/auth/user/', 'object_name': 'User'}], 'app_label': 'auth'}, {'has_module_perms': True, 'name': 'Lunchy', 'app_url': '/admin/lunchy/', 'models': [{'add_url': '/admin/lunchy/appointment/add/', 'name': <django.utils.functional.lazy.<locals>.__proxy__ object at 0x7ffb6d3e26d8>, 'perms': {'change': True, 'delete': True, 'add': True}, 'admin_url': '/admin/lunchy/appointment/', 'object_name': 'Appointment'}, {'add_url': '/admin/lunchy/availability/add/', 'name': <django.utils.functional.lazy.<locals>.__proxy__ object at 0x7ffb6d3e2630>, 'perms': {'change': True, 'delete': True, 'add': True}, 'admin_url': '/admin/lunchy/availability/', 'object_name': 'Availability'}, {'add_url': '/admin/lunchy/person/add/', 'name': <django.utils.functional.lazy.<locals>.__proxy__ object at 0x7ffb6d3e2278>, 'perms': {'change': True, 'delete': True, 'add': True}, 'admin_url': '/admin/lunchy/person/', 'object_name': 'Person'}, {'add_url': '/admin/lunchy/shortcut/add/', 'name': <django.utils.functional.lazy.<locals>.__proxy__ object at 0x7ffb6d357080>, 'perms': {'change': True, 'delete': True, 'add': True}, 'admin_url': '/admin/lunchy/shortcut/', 'object_name': 'Shortcut'}], 'app_label': 'lunchy'}], 'site_header': <django.utils.functional.lazy.<locals>.__proxy__ object at 0x7ffb7d15b240>, 'title': <django.utils.functional.lazy.<locals>.__proxy__ object at 0x7ffb7d164438>, 'has_permission': True, 'available_apps': [{'has_module_perms': True, 'name': <django.utils.functional.lazy.<locals>.__proxy__ object at 0x7ffb7d10e240>, 'app_url': '/admin/authtoken/', 'models': [{'add_url': '/admin/authtoken/token/add/', 'name': <django.utils.functional.lazy.<locals>.__proxy__ object at 0x7ffb6d357780>, 'perms': {'change': True, 'delete': True, 'add': True}, 'admin_url': '/admin/authtoken/token/', 'object_name': 'Token'}], 'app_label': 'authtoken'}, {'has_module_perms': True, 'name': <django.utils.functional.lazy.<locals>.__proxy__ object at 0x7ffb7d3d8320>, 'app_url': '/admin/auth/', 'models': [{'add_url': '/admin/auth/group/add/', 'name': <django.utils.functional.lazy.<locals>.__proxy__ object at 0x7ffb6d357320>, 'perms': {'change': True, 'delete': True, 'add': True}, 'admin_url': '/admin/auth/group/', 'object_name': 'Group'}, {'add_url': '/admin/auth/user/add/', 'name': <django.utils.functional.lazy.<locals>.__proxy__ object at 0x7ffb6d357160>, 'perms': {'change': True, 'delete': True, 'add': True}, 'admin_url': '/admin/auth/user/', 'object_name': 'User'}], 'app_label': 'auth'}, {'has_module_perms': True, 'name': 'Lunchy', 'app_url': '/admin/lunchy/', 'models': [{'add_url': '/admin/lunchy/appointment/add/', 'name': <django.utils.functional.lazy.<locals>.__proxy__ object at 0x7ffb6d3577b8>, 'perms': {'change': True, 'delete': True, 'add': True}, 'admin_url': '/admin/lunchy/appointment/', 'object_name': 'Appointment'}, {'add_url': '/admin/lunchy/availability/add/', 'name': <django.utils.functional.lazy.<locals>.__proxy__ object at 0x7ffb6d439c18>, 'perms': {'change': True, 'delete': True, 'add': True}, 'admin_url': '/admin/lunchy/availability/', 'object_name': 'Availability'}, {'add_url': '/admin/lunchy/person/add/', 'name': <django.utils.functional.lazy.<locals>.__proxy__ object at 0x7ffb6d357278>, 'perms': {'change': True, 'delete': True, 'add': True}, 'admin_url': '/admin/lunchy/person/', 'object_name': 'Person'}, {'add_url': '/admin/lunchy/shortcut/add/', 'name': <django.utils.functional.lazy.<locals>.__proxy__ object at 0x7ffb6d357668>, 'perms': {'change': True, 'delete': True, 'add': True}, 'admin_url': '/admin/lunchy/shortcut/', 'object_name': 'Shortcut'}], 'app_label': 'lunchy'}], 'site_url': '/', 'LANGUAGE_CODE': 'en-us', 'LANGUAGE_BIDI': False}]"
Exception while resolving variable 'is_popup' in template 'admin/index.html'.
Traceback (most recent call last):
  File "/home/cpasbanal/.virtualenvs/django19/lib/python3.5/site-packages/django/template/base.py", line 885, in _resolve_lookup
    current = current[bit]
  File "/home/cpasbanal/.virtualenvs/django19/lib/python3.5/site-packages/django/template/context.py", line 75, in __getitem__
    raise KeyError(key)
KeyError: 'is_popup'

During handling of the above exception, another exception occurred:

Traceback (most recent call last):
  File "/home/cpasbanal/.virtualenvs/django19/lib/python3.5/site-packages/django/template/base.py", line 891, in _resolve_lookup
    if isinstance(current, BaseContext) and getattr(type(current), bit):
AttributeError: type object 'RequestContext' has no attribute 'is_popup'

During handling of the above exception, another exception occurred:

Traceback (most recent call last):
  File "/home/cpasbanal/.virtualenvs/django19/lib/python3.5/site-packages/django/template/base.py", line 900, in _resolve_lookup
    current = current[int(bit)]
ValueError: invalid literal for int() with base 10: 'is_popup'

During handling of the above exception, another exception occurred:

Traceback (most recent call last):
  File "/home/cpasbanal/.virtualenvs/django19/lib/python3.5/site-packages/django/template/base.py", line 907, in _resolve_lookup
    (bit, current))  # missing attribute
django.template.base.VariableDoesNotExist: Failed lookup for key [is_popup] in "[{'False': False, 'None': None, 'True': True}, {'csrf_token': <SimpleLazyObject: <function csrf.<locals>._get_val at 0x7ffb6d4236a8>>, 'perms': <django.contrib.auth.context_processors.PermWrapper object at 0x7ffb6d3ebeb8>, 'messages': <django.contrib.messages.storage.fallback.FallbackStorage object at 0x7ffb6d3e2080>, 'user': <SimpleLazyObject: <User: jeremie>>, 'request': <WSGIRequest: GET '/admin/'>, 'DEFAULT_MESSAGE_LEVELS': {'SUCCESS': 25, 'ERROR': 40, 'DEBUG': 10, 'INFO': 20, 'WARNING': 30}}, {}, {'site_title': <django.utils.functional.lazy.<locals>.__proxy__ object at 0x7ffb7d15b198>, 'app_list': [{'has_module_perms': True, 'name': <django.utils.functional.lazy.<locals>.__proxy__ object at 0x7ffb7d10e240>, 'app_url': '/admin/authtoken/', 'models': [{'add_url': '/admin/authtoken/token/add/', 'name': <django.utils.functional.lazy.<locals>.__proxy__ object at 0x7ffb6d3e2128>, 'perms': {'change': True, 'delete': True, 'add': True}, 'admin_url': '/admin/authtoken/token/', 'object_name': 'Token'}], 'app_label': 'authtoken'}, {'has_module_perms': True, 'name': <django.utils.functional.lazy.<locals>.__proxy__ object at 0x7ffb7d3d8320>, 'app_url': '/admin/auth/', 'models': [{'add_url': '/admin/auth/group/add/', 'name': <django.utils.functional.lazy.<locals>.__proxy__ object at 0x7ffb6d357748>, 'perms': {'change': True, 'delete': True, 'add': True}, 'admin_url': '/admin/auth/group/', 'object_name': 'Group'}, {'add_url': '/admin/auth/user/add/', 'name': <django.utils.functional.lazy.<locals>.__proxy__ object at 0x7ffb6d3e2668>, 'perms': {'change': True, 'delete': True, 'add': True}, 'admin_url': '/admin/auth/user/', 'object_name': 'User'}], 'app_label': 'auth'}, {'has_module_perms': True, 'name': 'Lunchy', 'app_url': '/admin/lunchy/', 'models': [{'add_url': '/admin/lunchy/appointment/add/', 'name': <django.utils.functional.lazy.<locals>.__proxy__ object at 0x7ffb6d3e26d8>, 'perms': {'change': True, 'delete': True, 'add': True}, 'admin_url': '/admin/lunchy/appointment/', 'object_name': 'Appointment'}, {'add_url': '/admin/lunchy/availability/add/', 'name': <django.utils.functional.lazy.<locals>.__proxy__ object at 0x7ffb6d3e2630>, 'perms': {'change': True, 'delete': True, 'add': True}, 'admin_url': '/admin/lunchy/availability/', 'object_name': 'Availability'}, {'add_url': '/admin/lunchy/person/add/', 'name': <django.utils.functional.lazy.<locals>.__proxy__ object at 0x7ffb6d3e2278>, 'perms': {'change': True, 'delete': True, 'add': True}, 'admin_url': '/admin/lunchy/person/', 'object_name': 'Person'}, {'add_url': '/admin/lunchy/shortcut/add/', 'name': <django.utils.functional.lazy.<locals>.__proxy__ object at 0x7ffb6d357080>, 'perms': {'change': True, 'delete': True, 'add': True}, 'admin_url': '/admin/lunchy/shortcut/', 'object_name': 'Shortcut'}], 'app_label': 'lunchy'}], 'site_header': <django.utils.functional.lazy.<locals>.__proxy__ object at 0x7ffb7d15b240>, 'title': <django.utils.functional.lazy.<locals>.__proxy__ object at 0x7ffb7d164438>, 'has_permission': True, 'available_apps': [{'has_module_perms': True, 'name': <django.utils.functional.lazy.<locals>.__proxy__ object at 0x7ffb7d10e240>, 'app_url': '/admin/authtoken/', 'models': [{'add_url': '/admin/authtoken/token/add/', 'name': <django.utils.functional.lazy.<locals>.__proxy__ object at 0x7ffb6d357780>, 'perms': {'change': True, 'delete': True, 'add': True}, 'admin_url': '/admin/authtoken/token/', 'object_name': 'Token'}], 'app_label': 'authtoken'}, {'has_module_perms': True, 'name': <django.utils.functional.lazy.<locals>.__proxy__ object at 0x7ffb7d3d8320>, 'app_url': '/admin/auth/', 'models': [{'add_url': '/admin/auth/group/add/', 'name': <django.utils.functional.lazy.<locals>.__proxy__ object at 0x7ffb6d357320>, 'perms': {'change': True, 'delete': True, 'add': True}, 'admin_url': '/admin/auth/group/', 'object_name': 'Group'}, {'add_url': '/admin/auth/user/add/', 'name': <django.utils.functional.lazy.<locals>.__proxy__ object at 0x7ffb6d357160>, 'perms': {'change': True, 'delete': True, 'add': True}, 'admin_url': '/admin/auth/user/', 'object_name': 'User'}], 'app_label': 'auth'}, {'has_module_perms': True, 'name': 'Lunchy', 'app_url': '/admin/lunchy/', 'models': [{'add_url': '/admin/lunchy/appointment/add/', 'name': <django.utils.functional.lazy.<locals>.__proxy__ object at 0x7ffb6d3577b8>, 'perms': {'change': True, 'delete': True, 'add': True}, 'admin_url': '/admin/lunchy/appointment/', 'object_name': 'Appointment'}, {'add_url': '/admin/lunchy/availability/add/', 'name': <django.utils.functional.lazy.<locals>.__proxy__ object at 0x7ffb6d439c18>, 'perms': {'change': True, 'delete': True, 'add': True}, 'admin_url': '/admin/lunchy/availability/', 'object_name': 'Availability'}, {'add_url': '/admin/lunchy/person/add/', 'name': <django.utils.functional.lazy.<locals>.__proxy__ object at 0x7ffb6d357278>, 'perms': {'change': True, 'delete': True, 'add': True}, 'admin_url': '/admin/lunchy/person/', 'object_name': 'Person'}, {'add_url': '/admin/lunchy/shortcut/add/', 'name': <django.utils.functional.lazy.<locals>.__proxy__ object at 0x7ffb6d357668>, 'perms': {'change': True, 'delete': True, 'add': True}, 'admin_url': '/admin/lunchy/shortcut/', 'object_name': 'Shortcut'}], 'app_label': 'lunchy'}], 'site_url': '/', 'LANGUAGE_CODE': 'en-us', 'LANGUAGE_BIDI': False}]"
(0.009) SELECT "django_admin_log"."id", "django_admin_log"."action_time", "django_admin_log"."user_id", "django_admin_log"."content_type_id", "django_admin_log"."object_id", "django_admin_log"."object_repr", "django_admin_log"."action_flag", "django_admin_log"."change_message", "auth_user"."id", "auth_user"."password", "auth_user"."last_login", "auth_user"."is_superuser", "auth_user"."username", "auth_user"."first_name", "auth_user"."last_name", "auth_user"."email", "auth_user"."is_staff", "auth_user"."is_active", "auth_user"."date_joined", "django_content_type"."id", "django_content_type"."app_label", "django_content_type"."model" FROM "django_admin_log" INNER JOIN "auth_user" ON ("django_admin_log"."user_id" = "auth_user"."id") LEFT OUTER JOIN "django_content_type" ON ("django_admin_log"."content_type_id" = "django_content_type"."id") WHERE "django_admin_log"."user_id" = 1 ORDER BY "django_admin_log"."action_time" DESC LIMIT 10; args=(1,)
** Messenger API was called **
<QueryDict: {}>
Exception while resolving variable 'name' in template 'unknown'.
Traceback (most recent call last):
  File "/home/cpasbanal/.virtualenvs/django19/lib/python3.5/site-packages/django/core/handlers/exception.py", line 39, in inner
    response = get_response(request)
  File "/home/cpasbanal/.virtualenvs/django19/lib/python3.5/site-packages/django/core/handlers/base.py", line 249, in _legacy_get_response
    response = self._get_response(request)
  File "/home/cpasbanal/.virtualenvs/django19/lib/python3.5/site-packages/django/core/handlers/base.py", line 172, in _get_response
    resolver_match = resolver.resolve(request.path_info)
  File "/home/cpasbanal/.virtualenvs/django19/lib/python3.5/site-packages/django/urls/resolvers.py", line 297, in resolve
    raise Resolver404({'tried': tried, 'path': new_path})
django.urls.exceptions.Resolver404: {'path': 'favicon.ico', 'tried': [[<RegexURLResolver <module 'rest_framework.urls' from '/home/cpasbanal/.virtualenvs/django19/lib/python3.5/site-packages/rest_framework/urls.py'> (rest_framework:rest_framework) ^api-auth/>], [<RegexURLResolver <module 'lunchy.urls' from '/home/cpasbanal/randomlunch/lunchy/urls.py'> (None:None) ^lunchy/>], [<RegexURLResolver <RegexURLPattern list> (admin:admin) ^admin/>], [<RegexURLPattern None ^$>]]}

During handling of the above exception, another exception occurred:

Traceback (most recent call last):
  File "/home/cpasbanal/.virtualenvs/django19/lib/python3.5/site-packages/django/template/base.py", line 885, in _resolve_lookup
    current = current[bit]
TypeError: 'RegexURLResolver' object is not subscriptable

During handling of the above exception, another exception occurred:

Traceback (most recent call last):
  File "/home/cpasbanal/.virtualenvs/django19/lib/python3.5/site-packages/django/template/base.py", line 893, in _resolve_lookup
    current = getattr(current, bit)
AttributeError: 'RegexURLResolver' object has no attribute 'name'

During handling of the above exception, another exception occurred:

Traceback (most recent call last):
  File "/home/cpasbanal/.virtualenvs/django19/lib/python3.5/site-packages/django/template/base.py", line 900, in _resolve_lookup
    current = current[int(bit)]
ValueError: invalid literal for int() with base 10: 'name'

During handling of the above exception, another exception occurred:

Traceback (most recent call last):
  File "/home/cpasbanal/.virtualenvs/django19/lib/python3.5/site-packages/django/template/base.py", line 907, in _resolve_lookup
    (bit, current))  # missing attribute
django.template.base.VariableDoesNotExist: Failed lookup for key [name] in "<RegexURLResolver <module 'rest_framework.urls' from '/home/cpasbanal/.virtualenvs/django19/lib/python3.5/site-packages/rest_framework/urls.py'> (rest_framework:rest_framework) ^api-auth/>"
Exception while resolving variable 'name' in template 'unknown'.
Traceback (most recent call last):
  File "/home/cpasbanal/.virtualenvs/django19/lib/python3.5/site-packages/django/core/handlers/exception.py", line 39, in inner
    response = get_response(request)
  File "/home/cpasbanal/.virtualenvs/django19/lib/python3.5/site-packages/django/core/handlers/base.py", line 249, in _legacy_get_response
    response = self._get_response(request)
  File "/home/cpasbanal/.virtualenvs/django19/lib/python3.5/site-packages/django/core/handlers/base.py", line 172, in _get_response
    resolver_match = resolver.resolve(request.path_info)
  File "/home/cpasbanal/.virtualenvs/django19/lib/python3.5/site-packages/django/urls/resolvers.py", line 297, in resolve
    raise Resolver404({'tried': tried, 'path': new_path})
django.urls.exceptions.Resolver404: {'path': 'favicon.ico', 'tried': [[<RegexURLResolver <module 'rest_framework.urls' from '/home/cpasbanal/.virtualenvs/django19/lib/python3.5/site-packages/rest_framework/urls.py'> (rest_framework:rest_framework) ^api-auth/>], [<RegexURLResolver <module 'lunchy.urls' from '/home/cpasbanal/randomlunch/lunchy/urls.py'> (None:None) ^lunchy/>], [<RegexURLResolver <RegexURLPattern list> (admin:admin) ^admin/>], [<RegexURLPattern None ^$>]]}

During handling of the above exception, another exception occurred:

Traceback (most recent call last):
  File "/home/cpasbanal/.virtualenvs/django19/lib/python3.5/site-packages/django/template/base.py", line 885, in _resolve_lookup
    current = current[bit]
TypeError: 'RegexURLResolver' object is not subscriptable

During handling of the above exception, another exception occurred:

Traceback (most recent call last):
  File "/home/cpasbanal/.virtualenvs/django19/lib/python3.5/site-packages/django/template/base.py", line 893, in _resolve_lookup
    current = getattr(current, bit)
AttributeError: 'RegexURLResolver' object has no attribute 'name'

During handling of the above exception, another exception occurred:

Traceback (most recent call last):
  File "/home/cpasbanal/.virtualenvs/django19/lib/python3.5/site-packages/django/template/base.py", line 900, in _resolve_lookup
    current = current[int(bit)]
ValueError: invalid literal for int() with base 10: 'name'

During handling of the above exception, another exception occurred:

Traceback (most recent call last):
  File "/home/cpasbanal/.virtualenvs/django19/lib/python3.5/site-packages/django/template/base.py", line 907, in _resolve_lookup
    (bit, current))  # missing attribute
django.template.base.VariableDoesNotExist: Failed lookup for key [name] in "<RegexURLResolver <module 'lunchy.urls' from '/home/cpasbanal/randomlunch/lunchy/urls.py'> (None:None) ^lunchy/>"
Exception while resolving variable 'name' in template 'unknown'.
Traceback (most recent call last):
  File "/home/cpasbanal/.virtualenvs/django19/lib/python3.5/site-packages/django/core/handlers/exception.py", line 39, in inner
    response = get_response(request)
  File "/home/cpasbanal/.virtualenvs/django19/lib/python3.5/site-packages/django/core/handlers/base.py", line 249, in _legacy_get_response
    response = self._get_response(request)
  File "/home/cpasbanal/.virtualenvs/django19/lib/python3.5/site-packages/django/core/handlers/base.py", line 172, in _get_response
    resolver_match = resolver.resolve(request.path_info)
  File "/home/cpasbanal/.virtualenvs/django19/lib/python3.5/site-packages/django/urls/resolvers.py", line 297, in resolve
    raise Resolver404({'tried': tried, 'path': new_path})
django.urls.exceptions.Resolver404: {'path': 'favicon.ico', 'tried': [[<RegexURLResolver <module 'rest_framework.urls' from '/home/cpasbanal/.virtualenvs/django19/lib/python3.5/site-packages/rest_framework/urls.py'> (rest_framework:rest_framework) ^api-auth/>], [<RegexURLResolver <module 'lunchy.urls' from '/home/cpasbanal/randomlunch/lunchy/urls.py'> (None:None) ^lunchy/>], [<RegexURLResolver <RegexURLPattern list> (admin:admin) ^admin/>], [<RegexURLPattern None ^$>]]}

During handling of the above exception, another exception occurred:

Traceback (most recent call last):
  File "/home/cpasbanal/.virtualenvs/django19/lib/python3.5/site-packages/django/template/base.py", line 885, in _resolve_lookup
    current = current[bit]
TypeError: 'RegexURLResolver' object is not subscriptable

During handling of the above exception, another exception occurred:

Traceback (most recent call last):
  File "/home/cpasbanal/.virtualenvs/django19/lib/python3.5/site-packages/django/template/base.py", line 893, in _resolve_lookup
    current = getattr(current, bit)
AttributeError: 'RegexURLResolver' object has no attribute 'name'

During handling of the above exception, another exception occurred:

Traceback (most recent call last):
  File "/home/cpasbanal/.virtualenvs/django19/lib/python3.5/site-packages/django/template/base.py", line 900, in _resolve_lookup
    current = current[int(bit)]
ValueError: invalid literal for int() with base 10: 'name'

During handling of the above exception, another exception occurred:

Traceback (most recent call last):
  File "/home/cpasbanal/.virtualenvs/django19/lib/python3.5/site-packages/django/template/base.py", line 907, in _resolve_lookup
    (bit, current))  # missing attribute
django.template.base.VariableDoesNotExist: Failed lookup for key [name] in '<RegexURLResolver <RegexURLPattern list> (admin:admin) ^admin/>'
Not Found: /favicon.ico
** Messenger API was called **
<QueryDict: {}>
